异常（不论是RunTime还是Checked，）只要被catch捕获了，不管实际异常是否出现，try_catch块后面的语句一定正常执行。

但是如果异常出现，却没有被catch捕获，当前方法就直接结束，返回到被调用点